Workbook

Sheet uzdevumi
A1: Darblapā skola formatēt šūnu apgabala B2:B12 nelietojot tūkstošu atdalītāju.
A2: Darblapā skola šūnā D1 datuma formātā ievadīt datumu pirmdiena, 2015. gada 12. janvāris.
A3: Darblapā skola aizpildīt kolonnu F ar visu 2015. gada sestdienu datumiem.
A4: Darblapu lapa2 pārvietot uz jaunu, tukšu darbgrāmatu, jauno darbgrāmatu saglabāt kā veidni ar nosaukumu zals un aizvērt.
A5: Darblapā perimetrs izveidot līniju diagrammu, izmantojot datus no šūnu apgabala B2:C2;E2;B11:C18;E11:E18.
A6: Darblapā laukums dotajam grafikam pievienot virsrakstu Laukums.
A7: Darblapā vienādsānu šūnas A1 saturu centrēt šūnu apgabalā A1:K1.
A8: Darblapas vienādsānu šūnā K2 veikt teksta aplaušanu.
A9: Darblapas vienādsānu šūnā J3 ievadīt formulu, kas aprēķina, cik leņķu vērtības ir dotas A kolonnā.
A10: Darblapas vienādsānu šūnā K3 ievadīt formulu, kas aprēķina lielāko no A kolonnā dotajiem leņķiem.
A11: Darblapas vienādsānu šūnu apgabalā B3:B70 ievadīt formulu, kas izmantojot datus no kolonnas A, aprēķina vienādsānu trijstūra leņķi pie pamata.
A12: Darblapas vienādsānu šūnu apgabalā C3:C70 ievadīt formulu, kas izmantojot datus no kolonnām D, E un F pēc Hērona formulas aprēķina trijstūra laukumu
... A28: Darblapā pH uzraksti formulu, kas atrod lineāru sakarību (taisnes vienādojumu) starp pielieto nātrija hidroksīdu un pH līmeni.
A30: =28+9+2 -> 39

Sheet skola
A1: 2014./2015. mācību gads | D1: pirmdiena, 2015. gada 12. janvāris | F1: 42007
A2: Mācību gada sākums | B2: 41883 | F2: 42014
A3: Mācību gada beigas 1.–8.klases un 10.–11.klašu skolēniem | B3: 42153 | F3: 42021
A4: Mācību gada beigas 9. un 12. klašu skolēniem | B4: 42139 | F4: 42028
A5: Rudens brīvlaika sākums | B5: 41939 | F5: 42035
A6: Rudens brīvlaika beigas | B6: 41943 | F6: 42042
A7: Ziemas brīvlaika sākums | B7: 41995 | F7: 42049
A8: Ziemas brīvlaika beigas | B8: 42006 | F8: 42056
A9: Pavasara brīvlaika sākums 1. -11.klašu skolēniem | B9: 42079 | F9: 42063
A10: Pavasara brīvlaika beigas 1. -11.klašu skolēniem | B10: 42083 | F10: 42070
A11: Pavasara brīvlaika sākums 12. klašu skolēniem | B11: 42086 | F11: 42077
A12: Pavasara brīvlaika beigas 12. klašu skolēniem | B12: 42090 | F12: 42084
F13: 42091
A14: 1 | B14: Ddarblapā skola šūnu apgabalu B2:B12 formatēt, nelietojot tūkstošu atdalītāju. | F14: 42098
C15: 1 punkts | F15: 42105
F16: 42112
F17: 42119
A18: 2 | B18: Ddarblapā skola šūnā D1 datuma formātā ievadīt datumu pirmdiena, 2015. gada 12. janvāris. | F18: 42126
C19: 1 punkts | F19: 42133
F20: 42140
F21: 42147
A22: 3 | B22: Darblapā skola aizpildīt kolonnu F ar visu 2015. gada sestdienu datumiem. | F22: 42154
C23: 1 punkts | F23: 42161
F24: 42168
F25: 42175
F26: 42182
F27: 42189
F28: 42196
F29: 42203
F30: 42210
F31: 42217
F32: 42224
F33: 42231
F34: 42238
F35: 42245
... F52: 42364

Sheet perimetrs
A1: Taisnleņķa trijstūru perimetri
A2: leņķis1 | B2: leņķis2 | C2: leņķis3 | D2: hipotenūza | E2: perimetrs | P2: 5 | Q2: Darblapā perimetrs izveidot līniju diagrammu, izmantojot datus no šūnu apgabala B2:C2;E2;B11:C18;E11:E18. | V2: 2 punkti
A3: 90 | B3: 10 | C3: =90-B3 -> 80 | D3: 20 | E3: 43.169119
A4: 90 | B4: 20 | C4: =90-B4 -> 70 | D4: 20 | E4: 45.634255
A5: 90 | B5: 30 | C5: =90-B5 -> 60 | D5: 20 | E5: 47.320508
A6: 90 | B6: 40 | C6: =90-B6 -> 50 | D6: 20 | E6: 48.176641
A7: 90 | B7: 50 | C7: =90-B7 -> 40 | D7: 20 | E7: 48.176641
A8: 90 | B8: 60 | C8: =90-B8 -> 30 | D8: 20 | E8: 47.320508
A9: 90 | B9: 70 | C9: =90-B9 -> 20 | D9: 20 | E9: 45.634255
A10: 90 | B10: 80 | C10: =90-B10 -> 10 | D10: 20 | E10: 43.169119
A11: 90 | B11: 10 | C11: =90-B11 -> 80 | D11: 30 | E11: 64.753678
A12: 90 | B12: 20 | C12: =90-B12 -> 70 | D12: 30 | E12: 68.451383
A13: 90 | B13: 30 | C13: =90-B13 -> 60 | D13: 30 | E13: 70.980762
A14: 90 | B14: 40 | C14: =90-B14 -> 50 | D14: 30 | E14: 72.264962
... A26: 90 | B26: 80 | C26: =90-B26 -> 10 | D26: 40 | E26: 86.338237

Sheet laukums
A1: Taisnleņķa trijstūru laukumi
A2: leņķis1 | B2: leņķis2 | C2: leņķis3 | D2: hipotenūza | E2: laukums
A3: 90 | B3: 10 | C3: =90-B3 -> 80 | D3: 20 | E3: 34.202014 | S3: 6 | T3: Darblapā laukums dotajam grafikam pievienot virsrakstu Laukums. | W3: 1 punkts
A4: 90 | B4: 20 | C4: =90-B4 -> 70 | D4: 20 | E4: 64.278761
A5: 90 | B5: 30 | C5: =90-B5 -> 60 | D5: 20 | E5: 86.60254
A6: 90 | B6: 40 | C6: =90-B6 -> 50 | D6: 20 | E6: 98.480775
A7: 90 | B7: 50 | C7: =90-B7 -> 40 | D7: 20 | E7: 98.480775
A8: 90 | B8: 60 | C8: =90-B8 -> 30 | D8: 20 | E8: 86.60254
A9: 90 | B9: 70 | C9: =90-B9 -> 20 | D9: 20 | E9: 64.278761
A10: 90 | B10: 80 | C10: =90-B10 -> 10 | D10: 20 | E10: 34.202014
A11: 90 | B11: 10 | C11: =90-B11 -> 80 | D11: 30 | E11: 76.954532
A12: 90 | B12: 20 | C12: =90-B12 -> 70 | D12: 30 | E12: 144.62721
A13: 90 | B13: 30 | C13: =90-B13 -> 60 | D13: 30 | E13: 194.85572
A14: 90 | B14: 40 | C14: =90-B14 -> 50 | D14: 30 | E14: 221.58174
A15: 90 | B15: 50 | C15: =90-B15 -> 40 | D15: 30 | E15: 221.58174
... A26: 90 | B26: 80 | C26: =90-B26 -> 10 | D26: 40 | E26: 136.80806

Sheet vienādsānu
A1: Aprēķini vienādsānu trijstūrī
A2: alfa (leņķis pret pamatu) | B2: beta (leņķis pie pamata) | C2: S (laukums) | D2: a (pamats) | E2: b (sānu mala) | F2: c (sānu mala) | G2: p (perimetrs) | H2: h (augstums) | I2: tips | J2: skaits | K2: lielākais leņķis
A3: 89 | B3: =(180-A3)/2 -> 45.5 | C3: =SQRT((G3/2-D3)*(G3/2-E3)*(G3/2-F3)) -> 8.4258673 | D3: 11 | E3: 7.8469501 | F3: 7.8469501 | G3: =SUM(D3,F3,E3) -> 26.6939 | H3: =SQRT((E3*F3-(D3/2)*(D3/2))) -> 5.5968407 | I3: =IF(A3>90,"platlenķa","cits") -> cits | J3: =COUNT(A3:A70) -> 68 | K3: =MAX(A3:A70) -> 130
A4: 124 | B4: =(180-A4)/2 -> 28 | C4: =SQRT((G4/2-D4)*(G4/2-E4)*(G4/2-F4)) -> 4.696418 | D4: 11 | E4: 6.2291353 | F4: 6.2291353 | G4: =SUM(D4,F4,E4) -> 23.458271 | H4: =SQRT((E4*F4-(D4/2)*(D4/2))) -> 2.9244019 | I4: =IF(A4>90,"platlenķa","cits") -> platlenķa | L4: 7 | M4: Darblapā vienādsānu šūnas A1 saturu centrēt šūnu apgabalā A1:K1. | S4: 1 punkts
A5: 39 | B5: =(180-A5)/2 -> 70.5 | C5: =SQRT((G5/2-D5)*(G5/2-E5)*(G5/2-F5)) -> 20.762485 | D5: 12 | E5: 17.974466 | F5: 17.974466 | G5: =SUM(D5,F5,E5) -> 47.948932 | H5: =SQRT((E5*F5-(D5/2)*(D5/2))) -> 16.943477 | I5: =IF(A5>90,"platlenķa","cits") -> cits
A6: 99 | B6: =(180-A6)/2 -> 40.5 | C6: =SQRT((G6/2-D6)*(G6/2-E6)*(G6/2-F6)) -> 13.910529 | D6: 17 | E6: 11.178239 | F6: 11.178239 | G6: =SUM(D6,F6,E6) -> 39.356479 | H6: =SQRT((E6*F6-(D6/2)*(D6/2))) -> 7.2596858 | I6: =IF(A6>90,"platlenķa","cits") -> platlenķa
A7: 38 | B7: =(180-A7)/2 -> 71 | C7: =SQRT((G7/2-D7)*(G7/2-E7)*(G7/2-F7)) -> 67.462605 | D7: 26 | E7: 39.930195 | F7: 39.930195 | G7: =SUM(D7,F7,E7) -> 105.86039 | H7: =SQRT((E7*F7-(D7/2)*(D7/2))) -> 37.754741 | I7: =IF(A7>90,"platlenķa","cits") -> cits | L7: 8 | M7: Darblapas vienādsānu šūnā K2 veikt teksta aplaušanu. | S7: 1 punkts
A8: 100 | B8: =(180-A8)/2 -> 40 | C8: =SQRT((G8/2-D8)*(G8/2-E8)*(G8/2-F8)) -> 30.513477 | D8: 29 | E8: 18.928406 | F8: 18.928406 | G8: =SUM(D8,F8,E8) -> 66.856811 | H8: =SQRT((E8*F8-(D8/2)*(D8/2))) -> 12.166945 | I8: =IF(A8>90,"platlenķa","cits") -> platlenķa
A9: 54 | B9: =(180-A9)/2 -> 63 | C9: =SQRT((G9/2-D9)*(G9/2-E9)*(G9/2-F9)) -> 66.922825 | D9: 31 | E9: 34.141684 | F9: 34.141684 | G9: =SUM(D9,F9,E9) -> 99.283367 | H9: =SQRT((E9*F9-(D9/2)*(D9/2))) -> 30.420463 | I9: =IF(A9>90,"platlenķa","cits") -> cits | L9: 9 | M9: Darblapas vienādsānu šūnā J3 ievadīt formulu, kas aprēķina, cik leņķu vērtības ir dotas A kolonnā. | S9: 1 punkts
A10: 26 | B10: =(180-A10)/2 -> 77 | C10: =SQRT((G10/2-D10)*(G10/2-E10)*(G10/2-F10)) -> 124.40747 | D10: 33 | E10: 73.349289 | F10: 73.349289 | G10: =SUM(D10,F10,E10) -> 179.69858 | H10: =SQRT((E10*F10-(D10/2)*(D10/2))) -> 71.469352 | I10: =IF(A10>90,"platlenķa","cits") -> cits
A11: 126 | B11: =(180-A11)/2 -> 27 | C11: =SQRT((G11/2-D11)*(G11/2-E11)*(G11/2-F11)) -> 27.830269 | D11: 37 | E11: 20.763035 | F11: 20.763035 | G11: =SUM(D11,F11,E11) -> 78.526071 | H11: =SQRT((E11*F11-(D11/2)*(D11/2))) -> 9.4262208 | I11: =IF(A11>90,"platlenķa","cits") -> platlenķa
A12: 89 | B12: =(180-A12)/2 -> 45.5 | C12: =SQRT((G12/2-D12)*(G12/2-E12)*(G12/2-F12)) -> 58.427267 | D12: 40 | E12: 28.534364 | F12: 28.534364 | G12: =SUM(D12,F12,E12) -> 97.068728 | H12: =SQRT((E12*F12-(D12/2)*(D12/2))) -> 20.352148 | I12: =IF(A12>90,"platlenķa","cits") -> cits
A13: 37 | B13: =(180-A13)/2 -> 71.5 | C13: =SQRT((G13/2-D13)*(G13/2-E13)*(G13/2-F13)) -> 136.14636 | D13: 41 | E13: 64.606679 | F13: 64.606679 | G13: =SUM(D13,F13,E13) -> 170.21336 | H13: =SQRT((E13*F13-(D13/2)*(D13/2))) -> 61.268042 | I13: =IF(A13>90,"platlenķa","cits") -> cits | L13: 10 | M13: Darblapas vienādsānu šūnā K3 ievadīt formulu, kas aprēķina lielāko no A kolonnā dotajiem leņķiem. | S13: 1 punkts
A14: 38 | B14: =(180-A14)/2 -> 71 | C14: =SQRT((G14/2-D14)*(G14/2-E14)*(G14/2-F14)) -> 133.59151 | D14: 41 | E14: 62.966846 | F14: 62.966846 | G14: =SUM(D14,F14,E14) -> 166.93369 | H14: =SQRT((E14*F14-(D14/2)*(D14/2))) -> 59.536323 | I14: =IF(A14>90,"platlenķa","cits") -> cits
A15: 14 | B15: =(180-A15)/2 -> 83 | C15: =SQRT((G15/2-D15)*(G15/2-E15)*(G15/2-F15)) -> 267.60241 | D15: 43 | E15: 176.41844 | F15: 176.41844 | G15: =SUM(D15,F15,E15) -> 395.83689 | H15: =SQRT((E15*F15-(D15/2)*(D15/2))) -> 175.10345 | I15: =IF(A15>90,"platlenķa","cits") -> cits
A16: 75 | B16: =(180-A16)/2 -> 52.5 | C16: =SQRT((G16/2-D16)*(G16/2-E16)*(G16/2-F16)) -> 79.919905 | D16: 43 | E16: 35.317612 | F16: 35.317612 | G16: =SUM(D16,F16,E16) -> 113.63522 | H16: =SQRT((E16*F16-(D16/2)*(D16/2))) -> 28.019346 | I16: =IF(A16>90,"platlenķa","cits") -> cits
A17: 67 | B17: =(180-A17)/2 -> 56.5 | C17: =SQRT((G17/2-D17)*(G17/2-E17)*(G17/2-F17)) -> 89.821952 | D17: 43 | E17: 38.953722 | F17: 38.953722 | G17: =SUM(D17,F17,E17) -> 120.90744 | H17: =SQRT((E17*F17-(D17/2)*(D17/2))) -> 32.482957 | I17: =IF(A17>90,"platlenķa","cits") -> cits | L17: 11 | M17: Darblapas vienādsānu šūnu apgabalā B3:B70 ievadīt formulu, kas izmantojot datus no kolonnas A, aprēķina vienādsānu trijstūra leņķi pie pamata. | S17: 1 punkts
A18: 114 | B18: =(180-A18)/2 -> 33 | C18: =SQRT((G18/2-D18)*(G18/2-E18)*(G18/2-F18)) -> 46.809594 | D18: 45 | E18: 26.828174 | F18: 26.828174 | G18: =SUM(D18,F18,E18) -> 98.656348 | H18: =SQRT((E18*F18-(D18/2)*(D18/2))) -> 14.611671 | I18: =IF(A18>90,"platlenķa","cits") -> platlenķa
A19: 124 | B19: =(180-A19)/2 -> 28 | C19: =SQRT((G19/2-D19)*(G19/2-E19)*(G19/2-F19)) -> 38.859436 | D19: 45 | E19: 25.482826 | F19: 25.482826 | G19: =SUM(D19,F19,E19) -> 95.965652 | H19: =SQRT((E19*F19-(D19/2)*(D19/2))) -> 11.963462 | I19: =IF(A19>90,"platlenķa","cits") -> platlenķa
A20: 57 | B20: =(180-A20)/2 -> 61.5 | C20: =SQRT((G20/2-D20)*(G20/2-E20)*(G20/2-F20)) -> 115.46363 | D20: 46 | E20: 48.201986 | F20: 48.201986 | G20: =SUM(D20,F20,E20) -> 142.40397 | H20: =SQRT((E20*F20-(D20/2)*(D20/2))) -> 42.36073 | I20: =IF(A20>90,"platlenķa","cits") -> cits
A21: 90 | B21: =(180-A21)/2 -> 45 | C21: =SQRT((G21/2-D21)*(G21/2-E21)*(G21/2-F21)) -> 73.318564 | D21: 47 | E21: 33.234019 | F21: 33.234019 | G21: =SUM(D21,F21,E21) -> 113.46804 | H21: =SQRT((E21*F21-(D21/2)*(D21/2))) -> 23.5 | I21: =IF(A21>90,"platlenķa","cits") -> cits | L21: 12 | M21: Darblapas vienādsānu šūnu apgabalā C3:C70 ievadīt formulu, kas izmantojot datus no kolonnām D, E un F pēc Hērona formulas aprēķina trijstūra laukumu | S21: 2 punkti
A22: 45 | B22: =(180-A22)/2 -> 67.5 | C22: =SQRT((G22/2-D22)*(G22/2-E22)*(G22/2-F22)) -> 144.68914 | D22: 47 | E22: 61.408459 | F22: 61.408459 | G22: =SUM(D22,F22,E22) -> 169.81692 | H22: =SQRT((E22*F22-(D22/2)*(D22/2))) -> 56.734019 | I22: =IF(A22>90,"platlenķa","cits") -> cits
A23: 85 | B23: =(180-A23)/2 -> 47.5 | C23: =SQRT((G23/2-D23)*(G23/2-E23)*(G23/2-F23)) -> 108.2187 | D23: 58 | E23: 42.92543 | F23: 42.92543 | G23: =SUM(D23,F23,E23) -> 143.85086 | H23: =SQRT((E23*F23-(D23/2)*(D23/2))) -> 31.647947 | I23: =IF(A23>90,"platlenķa","cits") -> cits
A24: 42 | B24: =(180-A24)/2 -> 69 | C24: =SQRT((G24/2-D24)*(G24/2-E24)*(G24/2-F24)) -> 208.96591 | D24: 58 | E24: 80.922415 | F24: 80.922415 | G24: =SUM(D24,F24,E24) -> 219.84483 | H24: =SQRT((E24*F24-(D24/2)*(D24/2))) -> 75.547583 | I24: =IF(A24>90,"platlenķa","cits") -> cits
A25: 92 | B25: =(180-A25)/2 -> 44 | C25: =SQRT((G25/2-D25)*(G25/2-E25)*(G25/2-F25)) -> 102.63731 | D25: 60 | E25: 41.704908 | F25: 41.704908 | G25: =SUM(D25,F25,E25) -> 143.40982 | H25: =SQRT((E25*F25-(D25/2)*(D25/2))) -> 28.970663 | I25: =IF(A25>90,"platlenķa","cits") -> platlenķa | L25: 13 | M25: Darblapas vienādsānu šūnu apgabalā H3:H70 ievadīt formulu, kas izmantojot datus no kolonnām D un E, aprēķina vienādsānu trijstūra augstumu pret pamatu. | S25: 1 punkts
A26: 103 | B26: =(180-A26)/2 -> 38.5 | C26: =SQRT((G26/2-D26)*(G26/2-E26)*(G26/2-F26)) -> 88.776741 | D26: 61 | E26: 38.972249 | F26: 38.972249 | G26: =SUM(D26,F26,E26) -> 138.9445 | H26: =SQRT((E26*F26-(D26/2)*(D26/2))) -> 24.260795 | I26: =IF(A26>90,"platlenķa","cits") -> platlenķa
A27: 62 | B27: =(180-A27)/2 -> 59 | C27: =SQRT((G27/2-D27)*(G27/2-E27)*(G27/2-F27)) -> 167.4853 | D27: 62 | E27: 60.189725 | F27: 60.189725 | G27: =SUM(D27,F27,E27) -> 182.37945 | H27: =SQRT((E27*F27-(D27/2)*(D27/2))) -> 51.592664 | I27: =IF(A27>90,"platlenķa","cits") -> cits
A28: 109 | B28: =(180-A28)/2 -> 35.5 | C28: =SQRT((G28/2-D28)*(G28/2-E28)*(G28/2-F28)) -> 88.532676 | D28: 65 | E28: 39.920625 | F28: 39.920625 | G28: =SUM(D28,F28,E28) -> 144.84125 | H28: =SQRT((E28*F28-(D28/2)*(D28/2))) -> 23.182025 | I28: =IF(A28>90,"platlenķa","cits") -> platlenķa
A29: 96 | B29: =(180-A29)/2 -> 42 | C29: =SQRT((G29/2-D29)*(G29/2-E29)*(G29/2-F29)) -> 111.44956 | D29: 66 | E29: 44.40588 | F29: 44.40588 | G29: =SUM(D29,F29,E29) -> 154.81176 | H29: =SQRT((E29*F29-(D29/2)*(D29/2))) -> 29.713333 | I29: =IF(A29>90,"platlenķa","cits") -> platlenķa | L29: 14 | M29: Darblapas vienādsānu šūnu apgabalā G3:G70 dota formula, kas kļūdaini aprēķina vienādsānu trijstūra perimetru pēc sakarības p=a+b+c. Izlabot kļūdu, nemainot izmantoto funkciju. | S29: 1 punkts
A30: 118 | B30: =(180-A30)/2 -> 31 | C30: =SQRT((G30/2-D30)*(G30/2-E30)*(G30/2-F30)) -> 79.149511 | D30: 67 | E30: 39.082219 | F30: 39.082219 | G30: =SUM(D30,F30,E30) -> 145.16444 | H30: =SQRT((E30*F30-(D30/2)*(D30/2))) -> 20.128831 | I30: =IF(A30>90,"platlenķa","cits") -> platlenķa
A31: 96 | B31: =(180-A31)/2 -> 42 | C31: =SQRT((G31/2-D31)*(G31/2-E31)*(G31/2-F31)) -> 198.57293 | D31: 97 | E31: 65.263187 | F31: 65.263187 | G31: =SUM(D31,F31,E31) -> 227.52637 | H31: =SQRT((E31*F31-(D31/2)*(D31/2))) -> 43.669596 | I31: =IF(A31>90,"platlenķa","cits") -> platlenķa
A32: 14 | B32: =(180-A32)/2 -> 83 | C32: =SQRT((G32/2-D32)*(G32/2-E32)*(G32/2-F32)) -> 543.9525 | D32: 69 | E32: 283.09006 | F32: 283.09006 | G32: =SUM(D32,F32,E32) -> 635.18012 | H32: =SQRT((E32*F32-(D32/2)*(D32/2))) -> 280.97995 | I32: =IF(A32>90,"platlenķa","cits") -> cits
A33: 102 | B33: =(180-A33)/2 -> 39 | C33: =SQRT((G33/2-D33)*(G33/2-E33)*(G33/2-F33)) -> 113.2665 | D33: 71 | E33: 45.679965 | F33: 45.679965 | G33: =SUM(D33,F33,E33) -> 162.35993 | H33: =SQRT((E33*F33-(D33/2)*(D33/2))) -> 28.747333 | I33: =IF(A33>90,"platlenķa","cits") -> platlenķa
A34: 102 | B34: =(180-A34)/2 -> 39 | C34: =SQRT((G34/2-D34)*(G34/2-E34)*(G34/2-F34)) -> 113.2665 | D34: 71 | E34: 45.679965 | F34: 45.679965 | G34: =SUM(D34,F34,E34) -> 162.35993 | H34: =SQRT((E34*F34-(D34/2)*(D34/2))) -> 28.747333 | I34: =IF(A34>90,"platlenķa","cits") -> platlenķa | L34: 15 | M34: Darblapas vienādsānu šūnu apgabalā I3:I70 ievadīt formulu, kas aprēķina vienādsānu trijstūra tipu. Formulai jāparāda teksts „platleņķa”, ja A kolonnā dotais leņķis ir lielāks par 90, vai arī teksts „cits” pretējā gadījumā. | S34: 1 punkts
A35: 62 | B35: =(180-A35)/2 -> 59 | C35: =SQRT((G35/2-D35)*(G35/2-E35)*(G35/2-F35)) -> 218.39201 | D35: 74 | E35: 71.839349 | F35: 71.839349 | G35: =SUM(D35,F35,E35) -> 217.6787 | H35: =SQRT((E35*F35-(D35/2)*(D35/2))) -> 61.578341 | I35: =IF(A35>90,"platlenķa","cits") -> cits
A36: 50 | B36: =(180-A36)/2 -> 65 | C36: =SQRT((G36/2-D36)*(G36/2-E36)*(G36/2-F36)) -> 263.06313 | D36: 74 | E36: 87.549459 | F36: 87.549459 | G36: =SUM(D36,F36,E36) -> 249.09892 | H36: =SQRT((E36*F36-(D36/2)*(D36/2))) -> 79.346756 | I36: =IF(A36>90,"platlenķa","cits") -> cits
A37: 128 | B37: =(180-A37)/2 -> 26 | C37: =SQRT((G37/2-D37)*(G37/2-E37)*(G37/2-F37)) -> 80.161167 | D37: 77 | E37: 42.835175 | F37: 42.835175 | G37: =SUM(D37,F37,E37) -> 162.67035 | H37: =SQRT((E37*F37-(D37/2)*(D37/2))) -> 18.777705 | I37: =IF(A37>90,"platlenķa","cits") -> platlenķa
A38: 16 | B38: =(180-A38)/2 -> 82 | C38: =SQRT((G38/2-D38)*(G38/2-E38)*(G38/2-F38)) -> 605.72734 | D38: 78 | E38: 280.22656 | F38: 280.22656 | G38: =SUM(D38,F38,E38) -> 638.45313 | H38: =SQRT((E38*F38-(D38/2)*(D38/2))) -> 277.49942 | I38: =IF(A38>90,"platlenķa","cits") -> cits
A39: 11 | B39: =(180-A39)/2 -> 84.5 | C39: =SQRT((G39/2-D39)*(G39/2-E39)*(G39/2-F39)) -> 748.05191 | D39: 78 | E39: 406.90379 | F39: 406.90379 | G39: =SUM(D39,F39,E39) -> 891.80758 | H39: =SQRT((E39*F39-(D39/2)*(D39/2))) -> 405.03049 | I39: =IF(A39>90,"platlenķa","cits") -> cits
A40: 60 | B40: =(180-A40)/2 -> 60 | C40: =SQRT((G40/2-D40)*(G40/2-E40)*(G40/2-F40)) -> 262.52809 | D40: 82 | E40: 82 | F40: 82 | G40: =SUM(D40,F40,E40) -> 246 | H40: =SQRT((E40*F40-(D40/2)*(D40/2))) -> 71.014083 | I40: =IF(A40>90,"platlenķa","cits") -> cits
...

Sheet taisnleņķa
A1: Aprēķināt visu iespējamo taisnleņķa trijstūru laukumus
B2: hipotenūza
A3: leņķis grādos | B3: 10 | C3: 12 | D3: 14 | E3: 16 | F3: 18 | G3: 20 | J3: 16 | K3: Darblapas taisnleņķa šūnu apgabalā B4:G9 ievadīt formulu, kas izmantojot dotos datus, aprēķina visu taisnleņķa trijstūru laukumus. | P3: 3 punkti
A4: 20
A5: 30
A6: 40
A7: 50
A8: 60
A9: 70

Sheet dati1
A1: Aprēķini trijstūrī
A2: Trijstūra virsotņu koordinātes
A3: x1 | B3: y1 | C3: x2 | D3: y2 | E3: x3 | F3: y3 | G3: leņķis1 | H3: leņķis2 | I3: leņķis3 | J3: laukums | K3: mala1 | L3: mala2 | M3: mala3
A4: 81 | B4: -52 | C4: 74 | D4: 27 | E4: 75 | F4: 14 | G4: 179.20428 | H4: 0.6649115 | I4: 0.13081205 | J4: 12 | K4: 79.30952 | L4: 13.038405 | M4: 66.272166 | N4: =IF(AND(G4<90,H4<90,I4<90),"ir šaurlenķa","nav šaurlenķa") -> nav šaurlenķa | O4: 20 | P4: Darblapā dati1 sakārtot šūnu apgabala A4:M71 datus augošā secībā pēc laukuma vērtības. | T4: 1 punkts
A5: 53 | B5: -2 | C5: 53 | D5: -1 | E5: 6 | F5: -45 | G5: 0.65661637 | H5: 46.888188 | I5: 132.4552 | J5: 47 | K5: 1 | L5: 64.381674 | M5: 63.702433 | N5: =IF(AND(G5<90,H5<90,I5<90),"ir šaurlenķa","nav šaurlenķa") -> nav šaurlenķa
A6: 74 | B6: -96 | C6: 38 | D6: 10 | E6: 19 | F6: 64 | G6: 0.41410787 | H6: 179.37413 | I6: 0.21175746 | J6: 70 | K6: 111.94642 | L6: 57.245087 | M6: 169.18924 | N6: =IF(AND(G6<90,H6<90,I6<90),"ir šaurlenķa","nav šaurlenķa") -> nav šaurlenķa
A7: 74 | B7: 40 | C7: 73 | D7: 54 | E7: 65 | F7: -7 | G7: 3.3687463 | H7: 11.557176 | I7: 165.07408 | J7: 173 | K7: 14.035669 | L7: 61.522354 | M7: 47.853944 | N7: =IF(AND(G7<90,H7<90,I7<90),"ir šaurlenķa","nav šaurlenķa") -> nav šaurlenķa
A8: 77 | B8: 75 | C8: -65 | D8: -63 | E8: -81 | F8: -80 | G8: 2.2848486 | H8: 177.44584 | I8: 0.26931145 | J8: 206 | K8: 198.0101 | L8: 23.345235 | M8: 221.33459 | N8: =IF(AND(G8<90,H8<90,I8<90),"ir šaurlenķa","nav šaurlenķa") -> nav šaurlenķa | O8: 21 | P8: Darblapā dati1 šūnu apgabalā N4:N71 ievadīt formulu, kas pēc G, H un I kolonnās dotajām leņķu vērtībām nosaka atbilstošā trijstūra tipu. Formulai jāparāda teksts ir šaurleņķa, ja neviens no leņķiem nav lielāks par 90o, vai arī teksts nav šaurleņķa pretējā gadījumā. | T8: 2 punkti
A9: 53 | B9: 55 | C9: 55 | D9: 12 | E9: 50 | F9: 12 | G9: 86.009087 | H9: 87.336999 | I9: 6.6539139 | J9: 215 | K9: 43.046487 | L9: 5 | M9: 43.104524 | N9: =IF(AND(G9<90,H9<90,I9<90),"ir šaurlenķa","nav šaurlenķa") -> ir šaurlenķa
A10: 88 | B10: -95 | C10: 88 | D10: -88 | E10: 45 | F10: -57 | G10: 5.678732 | H10: 125.78897 | I10: 48.532295 | J10: 301 | K10: 7 | L10: 53.009433 | M10: 57.384667 | N10: =IF(AND(G10<90,H10<90,I10<90),"ir šaurlenķa","nav šaurlenķa") -> nav šaurlenķa
A11: -84 | B11: -61 | C11: -10 | D11: -13 | E11: -28 | F11: -29 | G11: 168.11134 | H11: 8.6641354 | I11: 3.2245226 | J11: 320 | K11: 88.204308 | L11: 24.083189 | M11: 64.498062 | N11: =IF(AND(G11<90,H11<90,I11<90),"ir šaurlenķa","nav šaurlenķa") -> nav šaurlenķa
A12: 82 | B12: -68 | C12: 40 | D12: 0 | E12: -26 | F12: 99 | G12: 0.79905251 | H12: 178.01136 | I12: 1.1895853 | J12: 330 | K12: 79.924965 | L12: 118.98319 | M12: 198.87936 | N12: =IF(AND(G12<90,H12<90,I12<90),"ir šaurlenķa","nav šaurlenķa") -> nav šaurlenķa
A13: -58 | B13: -88 | C13: -30 | D13: -16 | E13: -17 | F13: 30 | G13: 3.3794198 | H13: 174.53025 | I13: 2.0903324 | J13: 352 | K13: 77.252832 | L13: 47.801674 | M13: 124.91997 | N13: =IF(AND(G13<90,H13<90,I13<90),"ir šaurlenķa","nav šaurlenķa") -> nav šaurlenķa
A14: -51 | B14: -71 | C14: 88 | D14: 54 | E14: 22 | F14: -8 | G14: 177.58455 | H14: 1.2456585 | I14: 1.1697879 | J14: 368 | K14: 186.93849 | L14: 90.553851 | M14: 96.426138 | N14: =IF(AND(G14<90,H14<90,I14<90),"ir šaurlenķa","nav šaurlenķa") -> nav šaurlenķa
A15: -5 | B15: -73 | C15: -14 | D15: 12 | E15: -25 | F15: 58 | G15: 4.7681966 | H15: 172.59548 | I15: 2.6363263 | J15: 521 | K15: 85.475143 | L15: 47.296934 | M15: 132.51792 | N15: =IF(AND(G15<90,H15<90,I15<90),"ir šaurlenķa","nav šaurlenķa") -> nav šaurlenķa
A16: 65 | B16: -13 | C16: 74 | D16: 23 | E16: 72 | F16: 86 | G16: 5.8627885 | H16: 164.14545 | I16: 9.9917579 | J16: 639 | K16: 37.107951 | L16: 63.031738 | M16: 99.247166 | N16: =IF(AND(G16<90,H16<90,I16<90),"ir šaurlenķa","nav šaurlenķa") -> nav šaurlenķa
A17: -20 | B17: 22 | C17: 51 | D17: -7 | E17: 45 | F17: 5 | G17: 131.2218 | H17: 41.217355 | I17: 7.5608432 | J17: 678 | K17: 76.694198 | L17: 13.416408 | M17: 67.186308 | N17: =IF(AND(G17<90,H17<90,I17<90),"ir šaurlenķa","nav šaurlenķa") -> nav šaurlenķa
A18: -97 | B18: 76 | C18: 84 | D18: -55 | E18: 45 | F18: -32 | G18: 173.27442 | H18: 5.3656932 | I18: 1.3598903 | J18: 946 | K18: 223.43232 | L18: 45.276926 | M18: 178.40404 | N18: =IF(AND(G18<90,H18<90,I18<90),"ir šaurlenķa","nav šaurlenķa") -> nav šaurlenķa
A19: 25 | B19: -15 | C19: 21 | D19: -24 | E19: -91 | F19: 1 | G19: 4.7296492 | H19: 101.37953 | I19: 73.890824 | J19: 1108 | K19: 9.8488578 | L19: 114.75626 | M19: 117.09825 | N19: =IF(AND(G19<90,H19<90,I19<90),"ir šaurlenķa","nav šaurlenķa") -> nav šaurlenķa
A20: -6 | B20: -40 | C20: -31 | D20: 50 | E20: -54 | F20: 86 | G20: 11.719599 | H20: 162.95005 | I20: 5.330347 | J20: 1170 | K20: 93.407708 | L20: 42.720019 | M20: 134.83323 | N20: =IF(AND(G20<90,H20<90,I20<90),"ir šaurlenķa","nav šaurlenķa") -> nav šaurlenķa
... A50: 87 | B50: 45 | C50: -89 | D50: -57 | E50: 86 | F50: 5 | G50: 110.94061 | H50: 10.585732 | I50: 58.473662 | J50: 6938 | K50: 203.42075 | L50: 185.65829 | M50: 40.012498 | N50: =IF(AND(G50<90,H50<90,I50<90),"ir šaurlenķa","nav šaurlenķa") -> nav šaurlenķa
A51: -99 | B51: -95 | C51: -6 | D51: -94 | E51: -54 | F51: -10 | G51: 57.642152 | H51: 60.871179 | I51: 61.486669 | J51: 7860 | K51: 93.005376 | L51: 96.747093 | N51: =IF(AND(G51<90,H51<90,I51<90),"ir šaurlenķa","nav šaurlenķa") -> ir šaurlenķa
A52: 31 | B52: -86 | C52: 74 | D52: 2 | E52: -45 | F52: -51 | G52: 48.734461 | H52: 39.951037 | I52: 91.314502 | J52: 8193 | K52: 97.943861 | L52: 130.26895 | M52: 83.671979 | N52: =IF(AND(G52<90,H52<90,I52<90),"ir šaurlenķa","nav šaurlenķa") -> nav šaurlenķa
A53: -89 | B53: -79 | C53: -47 | D53: 10 | E53: 49 | F53: 4 | G53: 34.601109 | H53: 111.68676 | I53: 33.712127 | J53: 8796 | K53: 98.412398 | L53: 96.187317 | M53: 161.03726 | N53: =IF(AND(G53<90,H53<90,I53<90),"ir šaurlenķa","nav šaurlenķa") -> nav šaurlenķa
A54: -99 | B54: 57 | C54: -18 | D54: -23 | E54: -85 | F54: -67 | G54: 63.148037 | H54: 77.937693 | I54: 38.91427 | J54: 8924 | K54: 113.84639 | L54: 80.156098 | M54: 124.78782 | N54: =IF(AND(G54<90,H54<90,I54<90),"ir šaurlenķa","nav šaurlenķa") -> ir šaurlenķa
A55: -89 | B55: -7 | C55: -37 | D55: -55 | E55: 2 | F55: 85 | G55: 29.120594 | H55: 62.856928 | I55: 88.022479 | J55: 9152 | K55: 70.767224 | L55: 145.33066 | M55: 129.40247 | N55: =IF(AND(G55<90,H55<90,I55<90),"ir šaurlenķa","nav šaurlenķa") -> ir šaurlenķa
A56: -18 | B56: -76 | C56: 84 | D56: 52 | E56: 68 | F56: -62 | G56: 107.23544 | H56: 30.561139 | I56: 42.203422 | J56: 9580 | K56: 163.6704 | L56: 115.11733 | M56: 87.132084 | N56: =IF(AND(G56<90,H56<90,I56<90),"ir šaurlenķa","nav šaurlenķa") -> nav šaurlenķa
A57: 76 | B57: 33 | C57: -54 | D57: -14 | E57: -85 | F57: 52 | G57: 58.110214 | H57: 95.28243 | I57: 26.607356 | J57: 10037 | K57: 138.23531 | L57: 72.917762 | M57: 162.11724 | N57: =IF(AND(G57<90,H57<90,I57<90),"ir šaurlenķa","nav šaurlenķa") -> nav šaurlenķa
A58: -18 | B58: 72 | C58: 46 | D58: 59 | E58: -10 | F58: -93 | G58: 23.000663 | H58: 81.257132 | I58: 75.742205 | J58: 10456 | K58: 65.306967 | L58: 161.98765 | M58: 165.19383 | N58: =IF(AND(G58<90,H58<90,I58<90),"ir šaurlenķa","nav šaurlenķa") -> ir šaurlenķa
A59: -53 | B59: -86 | C59: 33 | D59: 13 | E59: -27 | F59: 68 | G59: 57.072498 | H59: 91.53003 | I59: 31.397473 | J59: 10670 | K59: 131.13733 | L59: 81.394103 | M59: 156.17938 | N59: =IF(AND(G59<90,H59<90,I59<90),"ir šaurlenķa","nav šaurlenķa") -> nav šaurlenķa
A60: 17 | B60: -12 | C60: 76 | D60: -83 | E60: 88 | F60: 98 | G60: 29.04734 | H60: 43.519168 | I60: 107.43349 | J60: 11531 | K60: 92.314679 | L60: 181.39735 | M60: 130.92364 | N60: =IF(AND(G60<90,H60<90,I60<90),"ir šaurlenķa","nav šaurlenķa") -> nav šaurlenķa
A61: 27 | B61: 98 | C61: -52 | D61: 42 | E61: -39 | F61: -95 | G61: 24.299689 | H61: 119.91074 | I61: 35.789575 | J61: 11551 | K61: 96.834911 | L61: 137.61541 | M61: 203.97304 | N61: =IF(AND(G61<90,H61<90,I61<90),"ir šaurlenķa","nav šaurlenķa") -> nav šaurlenķa
A62: 5 | B62: -43 | C62: -92 | D62: -48 | E62: 52 | F62: 86 | G62: 27.041351 | H62: 39.98911 | I62: 112.96954 | J62: 12278 | K62: 97.12878 | L62: 196.70282 | M62: 137.2953 | N62: =IF(AND(G62<90,H62<90,I62<90),"ir šaurlenķa","nav šaurlenķa") -> nav šaurlenķa
A63: -45 | B63: 21 | C63: 97 | D63: -65 | E63: -73 | F63: -50 | G63: 73.519851 | H63: 26.158064 | I63: 80.322086 | J63: 12490 | K63: 166.01205 | L63: 170.66048 | M63: 76.321688 | N63: =IF(AND(G63<90,H63<90,I63<90),"ir šaurlenķa","nav šaurlenķa") -> ir šaurlenķa
... A71: 24 | B71: 86 | C71: -51 | D71: -37 | E71: 95 | F71: -84 | G71: 49.487997 | H71: 76.471286 | I71: 54.040716 | J71: 21483 | K71: 144.06249 | L71: 153.37862 | M71: 184.23083 | N71: =IF(AND(G71<90,H71<90,I71<90),"ir šaurlenķa","nav šaurlenķa") -> ir šaurlenķa

Sheet dati2
A1: Aprēķini trijstūrī
A2: Trijstūra virsotņu koordinātes | N2: =AVERAGE(N4:N71) -> 326.47189
A3: x1 | B3: y1 | C3: x2 | D3: y2 | E3: x3 | F3: y3 | G3: leņķis1 | H3: leņķis2 | I3: leņķis3 | J3: laukums | K3: mala1 | L3: mala2 | M3: mala3 | N3: perimetrs
A4: -35 | B4: 97 | C4: 79 | D4: -4 | E4: -43 | F4: -27 | G4: 75.632258 | H4: 52.216172 | I4: 52.151569 | J4: 14944 | K4: 152.30561 | L4: 124.1491 | M4: 124.2578 | N4: 400.71251 | P4: 17 | Q4: Darblapai dati2 iesaldēt pirmās trīs rindas. | U4: 1 punkts
A5: -88 | B5: -69 | C5: 87 | D5: 17 | E5: -45 | F5: 58 | G5: 91.450099 | H5: 43.425931 | I5: 45.12397 | J5: 18527 | K5: 194.98974 | L5: 138.22084 | M5: 134.08206 | N5: 467.29265
A6: 43 | B6: -59 | C6: -93 | D6: -66 | E6: 8 | F6: 40 | G6: 63.086615 | H6: 43.43724 | I6: 73.476145 | J6: 13709 | K6: 136.18003 | L6: 146.4138 | M6: 105.00476 | N6: 387.59859 | P6: 18 | Q6: Darblapā dati2 formatēt šūnu apgabala G4:N71 datus kā decimālskaitļus ar trīs cipariem aiz komata. | U6: 1 punkts
A7: 97 | B7: -51 | C7: 72 | D7: -18 | E7: 10 | F7: -76 | G7: 27.058508 | H7: 84.055839 | I7: 68.885653 | J7: 3496 | K7: 41.400483 | L7: 84.899941 | M7: 90.520716 | N7: 216.82114
A8: -41 | B8: -26 | C8: -82 | D8: 62 | E8: 97 | F8: -42 | G8: 23.543367 | H8: 34.861933 | I8: 121.5947 | J8: 11488 | K8: 97.082439 | L8: 207.01932 | M8: 138.92444 | N8: 443.0262
A9: 46 | B9: -56 | C9: 5 | D9: 35 | E9: -1 | F9: 3 | G9: 130.83916 | H9: 34.873575 | I9: 14.287264 | J9: 1858 | K9: 99.809819 | L9: 32.557641 | M9: 75.432089 | N9: 207.79955
A10: 41 | B10: -70 | C10: 27 | D10: 76 | E10: -71 | F10: -81 | G10: 52.418158 | H10: 37.449936 | I10: 90.131906 | J10: 16506 | K10: 146.6697 | L10: 185.07566 | M10: 112.53888 | N10: 444.28424 | P10: 19 | Q10: Darblapā dati2 šūnā N2 ievadīt formulu, kas aprēķina vidējo no dotajiem trijstūru perimetriem. | U10: 1 punkts
A11: -28 | B11: -91 | C11: 73 | D11: 10 | E11: 21 | F11: 77 | G11: 54.075937 | H11: 97.184267 | I11: 28.739795 | J11: 12019 | K11: 142.83557 | L11: 84.811556 | M11: 175 | N11: 402.64713
A12: -14 | B12: -70 | C12: -25 | D12: 97 | E12: 73 | F12: 94 | G12: 63.808 | H12: 84.478065 | I12: 31.713935 | J12: 16333 | K12: 167.36188 | L12: 98.045908 | M12: 185.64752 | N12: 451.05531
A13: -59 | B13: 81 | C13: 2 | D13: -53 | E13: -16 | F13: -11 | G13: 178.14761 | H13: 1.277571 | I13: 0.57481631 | J13: 150 | K13: 147.23111 | L13: 45.694639 | M13: 101.55294 | N13: 294.47869
A14: -96 | B14: 47 | C14: 37 | D14: -44 | E14: 35 | F14: 71 | G14: 80.614543 | H14: 54.623307 | I14: 44.76215 | J14: 15113 | K14: 161.1521 | L14: 115.01739 | M14: 133.18033 | N14: 409.34982
A15: -7 | B15: -30 | C15: -72 | D15: -3 | E15: -75 | F15: -80 | G15: 51.441999 | H15: 69.673928 | I15: 58.884073 | J15: 5086 | K15: 70.384657 | L15: 77.058419 | M15: 84.403791 | N15: 231.84687
A16: 90 | B16: -17 | C16: 75 | D16: 81 | E16: 56 | F16: -22 | G16: 71.182481 | H16: 19.153857 | I16: 89.663662 | J16: 3407 | K16: 99.141313 | L16: 104.73777 | M16: 34.365681 | N16: 238.24476
A17: 59 | B17: -26 | C17: -82 | D17: -99 | E17: -13 | F17: -36 | G17: 145.50972 | H17: 15.025457 | I17: 19.464818 | J17: 3846 | K17: 158.77657 | L17: 93.434469 | M17: 72.691127 | N17: 324.90217
A18: -32 | B18: -6 | C18: 50 | D18: 35 | E18: 69 | F18: -82 | G18: 43.815522 | H18: 72.658871 | I18: 63.525607 | J18: 10373 | K18: 91.678787 | L18: 118.5327 | M18: 126.40016 | N18: 336.61164
A19: 88 | B19: 7 | C19: 6 | D19: 56 | E19: -58 | F19: 49 | G19: 22.290919 | H19: 142.89719 | I19: 14.811887 | J19: 3710 | K19: 95.524866 | L19: 64.381674 | M19: 151.92103 | N19: 311.82757
A20: -10 | B20: -10 | C20: 66 | D20: -27 | E20: 39 | F20: -80 | G20: 61.987859 | H20: 75.612768 | I20: 42.399373 | J20: 4487 | K20: 77.87811 | L20: 59.481089 | M20: 85.445889 | N20: 222.80509
A21: -20 | B21: -5 | C21: -20 | D21: 52 | E21: -57 | F21: -86 | G21: 9.5415387 | H21: 15.008914 | I21: 155.44955 | J21: 2109 | K21: 57 | L21: 142.87407 | M21: 89.050547 | N21: 288.92462
A22: 81 | B22: -85 | C22: 79 | D22: -10 | E22: -33 | F22: 39 | G22: 23.776593 | H22: 115.1569 | I22: 41.066504 | J22: 8302 | K22: 75.026662 | L22: 122.24974 | M22: 168.4399 | N22: 365.71631
... A71: 22 | B71: 41 | C71: -39 | D71: 45 | E71: 48 | F71: 97 | G71: 34.228422 | H71: 34.618539 | I71: 111.15304 | J71: 3520 | K71: 61.131007 | L71: 101.35581 | M71: 61.741396 | N71: 224.22821

Sheet pirkums
B1: XTR detaļu skaits pirkumā | C1: atlaide atbilstošajām XTR detaļām % | D1: Kopējā maksa par noteiktām detaļām
A2: Priekšējais pārslēdz. | B2: 2 | C2: 0 | L2: Darblapā pirkums šūnu apgabalā D2:D28 ievadīt formulu, kas aprēķina maksu par katru pirkumu, ņemot vērā detaļu skaitu, atlaides un cenu no darblapas cena.
A3: Aizmugurējais pārslēdz. | B3: 1 | C3: 0.035 | D3: =pirkums!J4*pirkums!B3-pirkums!C3*pirkums!B3*pirkums!J4 -> 0 | K3: 22 | Q3: 2 punkti
A4: Klaņi | B4: 2 | C4: 0.03 | D4: =pirkums!J5*pirkums!B4-pirkums!C4*pirkums!B4*pirkums!J5 -> 0
A5: Bremzes | B5: 2 | C5: 0.025 | D5: =pirkums!J6*pirkums!B5-pirkums!C5*pirkums!B5*pirkums!J6 -> 0
A6: Pārslēdzēja slēdži | B6: 2 | C6: 0.005 | D6: =pirkums!J7*pirkums!B6-pirkums!C6*pirkums!B6*pirkums!J7 -> 0
A7: Bremžu rokturi | B7: 2 | C7: 0.005 | D7: =pirkums!J8*pirkums!B7-pirkums!C7*pirkums!B7*pirkums!J8 -> 0
A8: Monobloks | B8: 1 | C8: 0.01 | D8: =pirkums!J9*pirkums!B8-pirkums!C8*pirkums!B8*pirkums!J9 -> 0 | K8: 23 | L8: Darblapā pirkums šūnā D29 ievadīt formulu, kas aprēķina pirkuma kopsummu. | Q8: 1 punkts
A9: Kasete | B9: 1 | C9: 0.01 | D9: =pirkums!J10*pirkums!B9-pirkums!C9*pirkums!B9*pirkums!J10 -> 0
A10: Ķēde | B10: 1 | C10: 0.015 | D10: =pirkums!J11*pirkums!B10-pirkums!C10*pirkums!B10*pirkums!J11 -> 0
A11: Priekšējā rumba | B11: 1 | C11: 0.03 | D11: =pirkums!J12*pirkums!B11-pirkums!C11*pirkums!B11*pirkums!J12 -> 0
A12: Aizmugurējā rumba | B12: 1 | C12: 0.02 | D12: =pirkums!J13*pirkums!B12-pirkums!C12*pirkums!B12*pirkums!J13 -> 0
A13: Diski | B13: 2 | C13: 0.025 | D13: =pirkums!J14*pirkums!B13-pirkums!C13*pirkums!B13*pirkums!J14 -> 0
A14: Amortizators | B14: 1 | C14: 0.02 | D14: =pirkums!J15*pirkums!B14-pirkums!C14*pirkums!B14*pirkums!J15 -> 0
A15: Spieķi | B15: 60 | C15: 0.03 | D15: =pirkums!J16*pirkums!B15-pirkums!C15*pirkums!B15*pirkums!J16 -> 0
A16: Sēdeklis | B16: 1 | C16: 0.025 | D16: =pirkums!J17*pirkums!B16-pirkums!C16*pirkums!B16*pirkums!J17 -> 0
A17: Sēdekļa stienis | B17: 1 | C17: 0.015 | D17: =pirkums!J18*pirkums!B17-pirkums!C17*pirkums!B17*pirkums!J18 -> 0
A18: Rāmis | B18: 1 | C18: 0.045 | D18: =pirkums!J19*pirkums!B18-pirkums!C18*pirkums!B18*pirkums!J19 -> 0
A19: Stūres stienis | B19: 1 | C19: 0.045 | D19: =pirkums!J20*pirkums!B19-pirkums!C19*pirkums!B19*pirkums!J20 -> 0
A20: Stūres iznesums | B20: 1 | C20: 0.025 | D20: =pirkums!J21*pirkums!B20-pirkums!C20*pirkums!B20*pirkums!J21 -> 0
A21: Radziņi | C21: 0.015 | D21: =pirkums!J22*pirkums!B21-pirkums!C21*pirkums!B21*pirkums!J22 -> 0
A22: Bļodiņas | C22: 0.05 | D22: =pirkums!J23*pirkums!B22-pirkums!C22*pirkums!B22*pirkums!J23 -> 0
A23: Trosītes | B23: 2 | C23: 0.04 | D23: =pirkums!J24*pirkums!B23-pirkums!C23*pirkums!B23*pirkums!J24 -> 0
A24: Pedāļi | B24: 2 | C24: 0.01 | D24: =pirkums!J25*pirkums!B24-pirkums!C24*pirkums!B24*pirkums!J25 -> 0
A25: Riepas | B25: 2 | C25: 0.035 | D25: =pirkums!J26*pirkums!B25-pirkums!C25*pirkums!B25*pirkums!J26 -> 0
A26: Kameras | B26: 2 | C26: 0.01
A27: Bremžu pastiprinātājs | C27: 0
A28: Trosīšu galiņi | B28: 4 | C28: 0.02
B29: Pirkuma kopsumma

Sheet cenas
B1: Cane | C1: Mavic | D1: Manitou | E1: Ritchy | F1: Selle | G1: Shimano | H1: Titec | I1: XT | J1: XTR | K1: WTB
A2: Priekšējais pārslēdz. | B2: 39.8 | C2: 28 | D2: 32.2 | E2: 33.6 | F2: 33.1 | G2: 37.1 | H2: 38.3 | I2: 40 | J2: Column1 | K2: 42.5
A3: Aizmugurējais pārslēdz. | B3: 74.9 | C3: 67.3 | D3: 81.5 | E3: 71.2 | F3: 68.2 | G3: 72.4 | H3: 81.3 | I3: 79 | J3: 25 | K3: 80.2
A4: Klaņi | B4: 198.2 | C4: 190.5 | D4: 202.8 | E4: 193.7 | F4: 190.7 | G4: 194.8 | H4: 197.5 | I4: 245 | J4: 50 | K4: 207.4
A5: Bremzes | B5: 99.4 | C5: 76.2 | D5: 97.1 | E5: 86.7 | F5: 82.3 | G5: 87.4 | H5: 98.1 | I5: 90 | J5: 135 | K5: 100.6
A6: Pārslēdzēja slēdži | B6: 97.3 | C6: 81.6 | D6: 139.8 | E6: 95.6 | F6: 83.6 | G6: 99 | H6: 137.8 | I6: 159 | J6: 70 | K6: 98.4
A7: Bremžu rokturi | B7: 73.4 | C7: 60 | D7: 77 | E7: 69.6 | F7: 61.7 | G7: 71.2 | H7: 86.3 | I7: 70 | J7: 70 | K7: 73
A8: Monobloks | B8: 36.8 | C8: 35.2 | D8: 46.4 | E8: 36.1 | F8: 35.4 | G8: 43 | H8: 36 | I8: 40 | J8: 60 | K8: 38.7
A9: Kasete | B9: 64.4 | C9: 62.4 | D9: 72.3 | E9: 68.9 | F9: 62.4 | G9: 67 | H9: 63.1 | I9: 80 | J9: 35 | K9: 69.9
A10: Ķēde | B10: 25.1 | C10: 17.5 | D10: 23.3 | E10: 20.3 | F10: 20.3 | G10: 24.3 | H10: 28.9 | I10: 20 | J10: 53 | K10: 34.1
A11: Priekšējā rumba | B11: 49.2 | C11: 43 | D11: 58.5 | E11: 47.1 | F11: 46.6 | G11: 48.8 | H11: 58.5 | I11: 55 | J11: 16 | K11: 54.1
A12: Aizmugurējā rumba | B12: 99.8 | C12: 77.2 | D12: 90.9 | E12: 83.7 | F12: 79.9 | G12: 89.7 | H12: 95.7 | I12: 100 | J12: 35 | K12: 92.2
A13: Diski | B13: 83.4 | C13: 122.4 | D13: 82.4 | E13: 93.1 | F13: 90.7 | G13: 101.5 | H13: 83.3 | I13: 50 | J13: 50 | K13: 89.7
A14: Amortizators | B14: 170.2 | C14: 284.8 | D14: 143.8 | E14: 177.9 | F14: 221.8 | G14: 175.6 | H14: 169.9 | I14: 129 | J14: 130 | K14: 174.4
... A28: Trosīšu galiņi | B28: 3.5 | C28: 10.4 | D28: 1.2 | E28: 7 | F28: 11.2 | G28: 14.5 | H28: 1.2 | I28: 1 | J28: 50 | K28: 4.1
J29: 1

Sheet velo
A1: Nr | B1: Grupa | C1: Uzvārds | D1: Vārds | E1: Klubs | F1: Laiks | G1: Ātrums | K1: 24 | L1: No lapas velo datiem jaunā darblapā iegūt kopsavilkuma tabulu, kurā būtu redzams cik bija dalībnieku, kuru vārds ir Kārlis. | Q1: 1 punkts
A2: 240 | B2: mtbW | C2: Ābele | D2: Ieva | E2: Rīga | F2: 2:03:17 | G2: 17.5
A3: 219 | B3: mtb M19 | C3: Ābelīte | D3: Renārs | F3: 1:17:53 | G3: 27.7
A4: 621 | B4: T M | C4: Ābelīts | D4: Sandis | E4: VIC velokurjers | F4: 1:02:55 | G4: 33.3
A5: 714 | B5: T M | C5: Ābelīts | D5: Valdis | E5: V-sports | F5: 1:22:23 | G5: 25.4
A6: 610 | B6: T M | C6: Ābeļkalns | D6: Ilvis | F6: 1:20:49 | G6: 25.9 | K6: 25 | L6: No lapas velo datiem jaunā darblapā iegūt kopsavilkuma tabulu, kurā būtu redzams, kāds bija katras kalnu velosipēdu (mtb) grupas dalībnieku vidējais ātrums. | Q6: 2 punkti
A7: 131 | B7: T M | C7: Ābiķis | D7: Dzintars | F7: 1:32:43 | G7: 22.6
A8: 220 | B8: T M | C8: Abiņš | D8: Juris | E8: Krāsu nams | F8: 1:01:59 | G8: 33.8
A9: 419 | B9: T M | C9: Āboliņš | D9: Gatis | E9: Viesnīca Santa | F9: 1:15:42 | G9: 27.7
A10: 535 | B10: T M | C10: Āboliņš | D10: Āris | F10: 1:23:20 | G10: 25.2
A11: 226 | B11: mtb M19 | C11: Adijāns | D11: Edgars | E11: Bosch | F11: 1:23:25 | G11: 25.8
A12: 623 | B12: T M | C12: Agejevs | D12: Aleksandrs | E12: VIC velokurjers | F12: 1:03:42 | G12: 32.9 | K12: 26 | L12: No lapas velo G kolonnas datiem izveidot histogrammu, kurā būtu redzams dalībnieku skaita sadalījums pēc vidējā ātruma intervālos pa 5km/h. | Q12: 2 punkti
A13: 104 | B13: T M | C13: Aizkalns | D13: Matīss | F13: 1:40:14 | G13: 20.9
A14: 104 | B14: T W | C14: Aizkalns | D14: Olita | E14: Jelgava | F14: 1:39:45 | G14: 21
A15: 241 | B15: mtb M16 | C15: Aizkalns | D15: Mārcis | E15: Jelgava | F15: 1:16:46 | G15: 28.1
A16: 242 | B16: mtb M36 | C16: Aizkalns | D16: Normunds | E16: Jelgava | F16: 1:50:53 | G16: 19.4
A17: 968 | B17: T M | C17: Aizups | D17: Andris | F17: 1:16:55 | G17: 27.3
A18: 921 | B18: T W | C18: Akmentiņa | D18: Laura | E18: Valmieras kom.Grods | F18: 1:59:21 | G18: 17.5
A19: 106 | B19: T M | C19: Āķis | D19: Mikus | E19: Rīga | F19: 1:41:19 | G19: 20.7
A20: 106 | B20: T M | C20: Āķis | D20: Helmuts | E20: Rīga | F20: 1:39:28 | G20: 21.1
A21: 220 | B21: mtb M19 | C21: Āķis | D21: Sandis | F21: 1:15:34 | G21: 28.5
A22: 127 | B22: T M | C22: Albāts | D22: Jānis | E22: Rīga | F22: 2:04:13 | G22: 16.9
A23: 142 | B23: T M | C23: Albāts | D23: Lauris | E23: Rīga | F23: 2:04:12 | G23: 16.9
A24: 822 | B24: T W | C24: Alberte | D24: Madara | F24: 1:10:22 | G24: 29.8
A25: 289 | B25: T M | C25: Alberts | D25: Māris | F25: 1:08:40 | G25: 30.5
A26: 130 | B26: T M | C26: Aleksandrovs | D26: Aleksandrs | E26: Veloserviss | F26: 0:57:37 | G26: 36.4
A27: 107 | B27: T M | C27: Aleksīns | D27: Viesturs | E27: Rīga | F27: 1:12:16 | G27: 29
A28: 221 | B28: mtb M46 | C28: Aliks | D28: Juris | F28: 1:52:09 | G28: 19.2
A29: 216 | B29: mtb M46 | C29: Alksnis | D29: Māris | F29: 1:30:07 | G29: 23.9
A30: 592 | B30: T M | C30: Alsiņš | D30: Reinis | F30: 1:28:52 | G30: 23.6
A31: 593 | B31: T M | C31: Alsiņš | D31: Modris | F31: 1:17:36 | G31: 27
A32: 142 | B32: T M | C32: Alviķis | D32: Pauls | E32: Sigulda | F32: 1:44:53 | G32: 20
A33: 7 | B33: M46 | C33: Aļeksejevs | D33: Leonīds | F33: 1:38:56 | G33: 43.3
A34: 223 | B34: mtb M36 | C34: Ambainis | D34: Aigars | F34: 1:10:30 | G34: 30.6
A35: 105 | B35: T M | C35: Ameters | D35: Armands | E35: Rīga | F35: 1:35:46 | G35: 21.9
A36: 672 | B36: T M | C36: Anderdorfs | D36: Janeks | E36: Ventspils | F36: 1:06:33 | G36: 31.5
A37: 219 | B37: mtb M36 | C37: Andersons | D37: Arvils | F37: 1:10:32 | G37: 30.6
A38: 500 | B38: T M | C38: Andersons | D38: Ilmārs | E38: Vello 31 | F38: 1:51:44 | G38: 18.7
A39: 357 | B39: T M | C39: Andrejevs | D39: Andrejs | E39: Valka | F39: 1:06:21 | G39: 31.6
A40: 436 | B40: T W | C40: Andrijanova | D40: Indra | F40: 1:30:50 | G40: 23.1
...

Sheet Sheet3

Sheet pH
A1: NaOH (ml) | B1: pH | E1: Šķīdumam pievienojot nātrija hidroksīdu, izmainās tā pH līmenis. Tabulā doti dati par pielieto nātrija hidroksīda daudzumu un pH līmeni.
A2: 0 | B2: 1 | D2: 27 | E2: Attēlo šos datus izkliedes diagrammā ar pievienotu polinomiālu tendenču līkni un tās raksturlielumiem - vienādojumu un korelācijas koeficientu. | R2: 2 punkti
A3: 10 | B3: 1.17 | D3: 28 | E3: Uzraksti formulu, kas atrod lineāru sakarību (taisnes vienādojumu) starp pielieto nātrija hidroksīdu un pH līmeni. | R3: 3 punkti
A4: 25 | B4: 1.48
A5: 45 | B5: 2.28
A6: 49.5 | B6: 3.3
A7: 49.75 | B7: 3.6
A8: 50 | B8: 7 | R8: `
A9: 50.25 | B9: 10.4
A10: 55 | B10: 11.68
A11: 60 | B11: 11.96
